<?xml version="1.0" ?>
<!-- Generated using onshape-to-robot -->
<!-- Onshape https://cad.onshape.com/documents/3e708ce27c0b38dcdf8ce5c5/w/d2322db6571afcc498723ba0/e/6adea148584488a7fd0652e6 -->
<robot name="onshape">
  <!-- Link chassis -->
  <link name="chassis">
    <inertial>
      <origin xyz="-0.00627312 0.000372119 0.00126341" rpy="0 0 0"/>
      <mass value="0.158971"/>
      <inertia ixx="0.000240792" ixy="-2.70106e-08" ixz="2.9522e-08" iyy="0.000102224" iyz="-5.77714e-06" izz="0.000322753"/>
    </inertial>
    <!-- Part tail_2 -->
    <visual>
      <origin xyz="-0.00639673 0.00254125 -0.0007563" rpy="-7.64786e-13 -3.43475e-16 -5.96644e-17"/>
      <geometry>
        <mesh filename="package://assets/tail.stl"/>
      </geometry>
      <material name="tail_2_material">
        <color rgba="0.443137 0.431373 0.431373 1"/>
      </material>
    </visual>
    <!-- Part cover -->
    <visual>
      <origin xyz="-0.00639673 0.00234125 -0.0003563" rpy="-7.64786e-13 -3.43475e-16 -5.96644e-17"/>
      <geometry>
        <mesh filename="package://assets/cover.stl"/>
      </geometry>
      <material name="cover_material">
        <color rgba="0.286275 0.286275 0.27451 1"/>
      </material>
    </visual>
    <!-- Part front -->
    <visual>
      <origin xyz="-0.00629673 0.00251371 -0.000404366" rpy="-7.64666e-13 -2.77556e-17 -5.55112e-17"/>
      <geometry>
        <mesh filename="package://assets/front.stl"/>
      </geometry>
      <material name="front_material">
        <color rgba="0 0.65098 1 1"/>
      </material>
    </visual>
    <!-- Part front_2 -->
    <visual>
      <origin xyz="-0.00629673 0.00216879 -0.000404366" rpy="7.64666e-13 2.77556e-17 -3.14159"/>
      <geometry>
        <mesh filename="package://assets/front.stl"/>
      </geometry>
      <material name="front_2_material">
        <color rgba="0 0.65098 1 1"/>
      </material>
    </visual>
    <!-- Part chassis -->
    <visual>
      <origin xyz="-0.00626294 0.0023266 -0.000269781" rpy="0 -0 0"/>
      <geometry>
        <mesh filename="package://assets/chassis.stl"/>
      </geometry>
      <material name="chassis_material">
        <color rgba="0.980392 0.647059 0.239216 1"/>
      </material>
    </visual>
    <!-- Part shoulder -->
    <visual>
      <origin xyz="-0.00629673 0.00234125 -0.000503935" rpy="-7.64666e-13 -2.77556e-17 -5.55112e-17"/>
      <geometry>
        <mesh filename="package://assets/shoulder.stl"/>
      </geometry>
      <material name="shoulder_material">
        <color rgba="0.980392 0.647059 0.239216 1"/>
      </material>
    </visual>
    <!-- Part neck -->
    <visual>
      <origin xyz="-0.00626294 0.00229975 -0.000169598" rpy="4.06342e-13 -0 0"/>
      <geometry>
        <mesh filename="package://assets/neck.stl"/>
      </geometry>
      <material name="neck_material">
        <color rgba="0.980392 0.647059 0.239216 1"/>
      </material>
    </visual>
    <!-- Part 809_25_v1 -->
    <visual>
      <origin xyz="-0.00626294 -0.0432543 0.010307" rpy="0 -0.523599 1.5708"/>
      <geometry>
        <mesh filename="package://assets/809_25_v1.stl"/>
      </geometry>
      <material name="809_25_v1_material">
        <color rgba="0.752941 0.752941 0.752941 1"/>
      </material>
    </visual>
    <!-- Part shoulder_2 -->
    <visual>
      <origin xyz="-0.00622916 0.00231194 -0.000503935" rpy="7.64666e-13 -2.77556e-17 3.14159"/>
      <geometry>
        <mesh filename="package://assets/shoulder.stl"/>
      </geometry>
      <material name="shoulder_2_material">
        <color rgba="0.980392 0.647059 0.239216 1"/>
      </material>
    </visual>
    <!-- Part battcase -->
    <visual>
      <origin xyz="-0.00626294 0.00216463 -0.000369781" rpy="9.25186e-17 -3.69239e-32 -3.41615e-48"/>
      <geometry>
        <mesh filename="package://assets/battcase.stl"/>
      </geometry>
      <material name="battcase_material">
        <color rgba="0.286275 0.286275 0.27451 1"/>
      </material>
    </visual>
    <!-- Part battlid -->
    <visual>
      <origin xyz="-0.00626294 0.00216463 -0.000469781" rpy="1.00774e-16 -3.68589e-32 -3.41013e-48"/>
      <geometry>
        <mesh filename="package://assets/battlid.stl"/>
      </geometry>
      <material name="battlid_material">
        <color rgba="0.6 0.6 0.580392 1"/>
      </material>
    </visual>
    <!-- Part kp_v5_shaft -->
    <visual>
      <origin xyz="0.0150033 0.057074 -0.00883669" rpy="-0.523599 -4.85723e-17 1.68824e-17"/>
      <geometry>
        <mesh filename="package://assets/kp_v5_shaft.stl"/>
      </geometry>
      <material name="kp_v5_shaft_material">
        <color rgba="0.627451 0.627451 0.627451 1"/>
      </material>
    </visual>
    <!-- Part kp_v5_body -->
    <visual>
      <origin xyz="0.0150033 0.057074 -0.00883669" rpy="-0.523599 -2.08167e-17 1.05264e-29"/>
      <geometry>
        <mesh filename="package://assets/kp_v5_body.stl"/>
      </geometry>
      <material name="kp_v5_body_material">
        <color rgba="0.152941 0.239216 0.2 1"/>
      </material>
    </visual>
    <!-- Part kp_v5_shaft_2 -->
    <visual>
      <origin xyz="0.0150033 -0.0584915 0.00172882" rpy="-2.61799 -0 1.08732e-17"/>
      <geometry>
        <mesh filename="package://assets/kp_v5_shaft.stl"/>
      </geometry>
      <material name="kp_v5_shaft_2_material">
        <color rgba="0.627451 0.627451 0.627451 1"/>
      </material>
    </visual>
    <!-- Part kp_v5_body_2 -->
    <visual>
      <origin xyz="0.0150033 -0.0584915 0.00172882" rpy="-2.61799 -2.08167e-17 1.05264e-29"/>
      <geometry>
        <mesh filename="package://assets/kp_v5_body.stl"/>
      </geometry>
      <material name="kp_v5_body_2_material">
        <color rgba="0.152941 0.239216 0.2 1"/>
      </material>
    </visual>
    <!-- Part kp_v5_shaft_3 -->
    <visual>
      <origin xyz="-0.0275292 -0.0524208 -0.00883669" rpy="-0.523599 -4.85723e-17 -3.14159"/>
      <geometry>
        <mesh filename="package://assets/kp_v5_shaft.stl"/>
      </geometry>
      <material name="kp_v5_shaft_3_material">
        <color rgba="0.627451 0.627451 0.627451 1"/>
      </material>
    </visual>
    <!-- Part kp_v5_body_3 -->
    <visual>
      <origin xyz="-0.0275292 -0.0524208 -0.00883669" rpy="-0.523599 -2.08167e-17 3.14159"/>
      <geometry>
        <mesh filename="package://assets/kp_v5_body.stl"/>
      </geometry>
      <material name="kp_v5_body_3_material">
        <color rgba="0.152941 0.239216 0.2 1"/>
      </material>
    </visual>
    <!-- Part kp_v5_shaft_4 -->
    <visual>
      <origin xyz="-0.0275292 0.0631447 0.00172882" rpy="-2.61799 -0 -3.14159"/>
      <geometry>
        <mesh filename="package://assets/kp_v5_shaft.stl"/>
      </geometry>
      <material name="kp_v5_shaft_4_material">
        <color rgba="0.627451 0.627451 0.627451 1"/>
      </material>
    </visual>
    <!-- Part kp_v5_body_4 -->
    <visual>
      <origin xyz="-0.0275292 0.0631447 0.00172882" rpy="-2.61799 -2.08167e-17 3.14159"/>
      <geometry>
        <mesh filename="package://assets/kp_v5_body.stl"/>
      </geometry>
      <material name="kp_v5_body_4_material">
        <color rgba="0.152941 0.239216 0.2 1"/>
      </material>
    </visual>
  </link>
  <!-- Frame left_front_shoulder (dummy link + fixed joint) -->
  <link name="left_front_shoulder">
    <origin xyz="0 0 0" rpy="0 -0 0"/>
    <inertial>
      <origin xyz="0 0 0" rpy="0 0 0"/>
      <mass value="1e-9"/>
      <inertia ixx="0" ixy="0" ixz="0" iyy="0" iyz="0" izz="0"/>
    </inertial>
  </link>
  <joint name="left_front_shoulder_frame" type="fixed">
    <origin xyz="0.0347033 -0.0501588 -0.000503935" rpy="-1.5708 0.523599 -1.5708"/>
    <parent link="chassis"/>
    <child link="left_front_shoulder"/>
    <axis xyz="0 0 0"/>
  </joint>
  <!-- Frame right_front_shoulder (dummy link + fixed joint) -->
  <link name="right_front_shoulder">
    <origin xyz="0 0 0" rpy="0 -0 0"/>
    <inertial>
      <origin xyz="0 0 0" rpy="0 0 0"/>
      <mass value="1e-9"/>
      <inertia ixx="0" ixy="0" ixz="0" iyy="0" iyz="0" izz="0"/>
    </inertial>
  </link>
  <joint name="right_front_shoulder_frame" type="fixed">
    <origin xyz="-0.0472292 -0.0501881 -0.000503935" rpy="1.5708 0.523599 -1.5708"/>
    <parent link="chassis"/>
    <child link="right_front_shoulder"/>
    <axis xyz="0 0 0"/>
  </joint>
  <!-- Frame right_back_shoulder (dummy link + fixed joint) -->
  <link name="right_back_shoulder">
    <origin xyz="0 0 0" rpy="0 -0 0"/>
    <inertial>
      <origin xyz="0 0 0" rpy="0 0 0"/>
      <mass value="1e-9"/>
      <inertia ixx="0" ixy="0" ixz="0" iyy="0" iyz="0" izz="0"/>
    </inertial>
  </link>
  <joint name="right_back_shoulder_frame" type="fixed">
    <origin xyz="-0.0472292 0.0548119 -0.000503935" rpy="-1.5708 0.523599 1.5708"/>
    <parent link="chassis"/>
    <child link="right_back_shoulder"/>
    <axis xyz="0 0 0"/>
  </joint>
  <!-- Frame left_back_shoulder (dummy link + fixed joint) -->
  <link name="left_back_shoulder">
    <origin xyz="0 0 0" rpy="0 -0 0"/>
    <inertial>
      <origin xyz="0 0 0" rpy="0 0 0"/>
      <mass value="1e-9"/>
      <inertia ixx="0" ixy="0" ixz="0" iyy="0" iyz="0" izz="0"/>
    </inertial>
  </link>
  <joint name="left_back_shoulder_frame" type="fixed">
    <origin xyz="0.0347033 0.0548412 -0.000503935" rpy="1.5708 0.523599 1.5708"/>
    <parent link="chassis"/>
    <child link="left_back_shoulder"/>
    <axis xyz="0 0 0"/>
  </joint>
  <!-- Frame tail (dummy link + fixed joint) -->
  <link name="tail">
    <origin xyz="0 0 0" rpy="0 -0 0"/>
    <inertial>
      <origin xyz="0 0 0" rpy="0 0 0"/>
      <mass value="1e-9"/>
      <inertia ixx="0" ixy="0" ixz="0" iyy="0" iyz="0" izz="0"/>
    </inertial>
  </link>
  <joint name="tail_frame" type="fixed">
    <origin xyz="-0.00639673 0.085276 0.0444891" rpy="-7.64786e-13 -3.43475e-16 -5.96644e-17"/>
    <parent link="chassis"/>
    <child link="tail"/>
    <axis xyz="0 0 0"/>
  </joint>
  <!-- Link bittle_x_leg -->
  <link name="bittle_x_leg">
    <inertial>
      <origin xyz="-0.023 1.03756e-06 -0.00195" rpy="0 0 0"/>
      <mass value="0.00320032"/>
      <inertia ixx="6.4702e-08" ixy="-4.32909e-14" ixz="-4.44657e-08" iyy="1.08313e-06" iyz="-1.92002e-15" izz="1.11945e-06"/>
    </inertial>
    <!-- Part springs_v2 -->
    <visual>
      <origin xyz="-0.0100472 0.000102873 -0.000991506" rpy="-1.51844 4.99211e-05 -1.57175"/>
      <geometry>
        <mesh filename="package://assets/springs_v2.stl"/>
      </geometry>
      <material name="springs_v2_material">
        <color rgba="0.956863 0.898039 0.654902 1"/>
      </material>
    </visual>
    <!-- Part 809_25_v1_2 -->
    <visual>
      <origin xyz="-0.046 3.68636e-13 -0.00265" rpy="2.77413e-16 -1.38778e-17 3.14159"/>
      <geometry>
        <mesh filename="package://assets/809_25_v1.stl"/>
      </geometry>
      <material name="809_25_v1_2_material">
        <color rgba="0.752941 0.752941 0.752941 1"/>
      </material>
    </visual>
    <!-- Part 809_25_v1_3 -->
    <visual>
      <origin xyz="1.0842e-19 -6.93889e-18 -0.0005" rpy="-2.83643e-33 7.70372e-34 -8.8823e-29"/>
      <geometry>
        <mesh filename="package://assets/809_25_v1.stl"/>
      </geometry>
      <material name="809_25_v1_3_material">
        <color rgba="0.752941 0.752941 0.752941 1"/>
      </material>
    </visual>
    <!-- Part springs_v2_2 -->
    <visual>
      <origin xyz="-0.0429436 9.56526e-05 -0.00327486" rpy="-1.51844 -5.39851e-05 -1.56977"/>
      <geometry>
        <mesh filename="package://assets/springs_v2.stl"/>
      </geometry>
      <material name="springs_v2_2_material">
        <color rgba="0.956863 0.898039 0.654902 1"/>
      </material>
    </visual>
    <!-- Part thighsym_lower -->
    <visual>
      <origin xyz="0.03 3.68289e-13 -0.002025" rpy="-1.5708 -1.38778e-17 -1.27782e-27"/>
      <geometry>
        <mesh filename="package://assets/thighsym_lower.stl"/>
      </geometry>
      <material name="thighsym_lower_material">
        <color rgba="0.356863 0.360784 0.368627 1"/>
      </material>
    </visual>
    <!-- Part thighsym_upper -->
    <visual>
      <origin xyz="0.03 1.40166e-15 -0.00195" rpy="-1.5708 -6.93889e-18 -6.83322e-28"/>
      <geometry>
        <mesh filename="package://assets/thighsym_upper.stl"/>
      </geometry>
      <material name="thighsym_upper_material">
        <color rgba="0.980392 0.647059 0.239216 1"/>
      </material>
    </visual>
  </link>
  <!-- Frame left_front_knee (dummy link + fixed joint) -->
  <link name="left_front_knee">
    <origin xyz="0 0 0" rpy="0 -0 0"/>
    <inertial>
      <origin xyz="0 0 0" rpy="0 0 0"/>
      <mass value="1e-9"/>
      <inertia ixx="0" ixy="0" ixz="0" iyy="0" iyz="0" izz="0"/>
    </inertial>
  </link>
  <joint name="left_front_knee_frame" type="fixed">
    <origin xyz="-0.0554318 3.16934e-13 -0.0041" rpy="1.5708 -1.38778e-17 5.36902e-12"/>
    <parent link="bittle_x_leg"/>
    <child link="left_front_knee"/>
    <axis xyz="0 0 0"/>
  </joint>
  <!-- Link bittle_x_shank_left -->
  <link name="bittle_x_shank_left">
    <inertial>
      <origin xyz="-0.00799662 0.00014001 -0.0160518" rpy="0 0 0"/>
      <mass value="0.0163164"/>
      <inertia ixx="7.33351e-07" ixy="2.14772e-08" ixz="-1.54392e-07" iyy="2.51211e-06" iyz="1.02325e-09" izz="2.23017e-06"/>
    </inertial>
    <!-- Part shank -->
    <visual>
      <origin xyz="0.0061 -0.0061 -0.0272" rpy="-1.5708 -1.5708 0"/>
      <geometry>
        <mesh filename="package://assets/shank.stl"/>
      </geometry>
      <material name="shank_material">
        <color rgba="0.286275 0.286275 0.27451 1"/>
      </material>
    </visual>
    <!-- Part kp_v5_shaft_5 -->
    <visual>
      <origin xyz="0.0061 -0.0061 -0.0272" rpy="-1.5708 -1.5708 0"/>
      <geometry>
        <mesh filename="package://assets/kp_v5_shaft.stl"/>
      </geometry>
      <material name="kp_v5_shaft_5_material">
        <color rgba="0.627451 0.627451 0.627451 1"/>
      </material>
    </visual>
    <!-- Part kp_v5_body_5 -->
    <visual>
      <origin xyz="0.0061 -0.0061 -0.0272" rpy="-1.5708 -1.5708 0"/>
      <geometry>
        <mesh filename="package://assets/kp_v5_body.stl"/>
      </geometry>
      <material name="kp_v5_body_5_material">
        <color rgba="0.152941 0.239216 0.2 1"/>
      </material>
    </visual>
  </link>
  <!-- Frame left_front_foot (dummy link + fixed joint) -->
  <link name="left_front_foot">
    <origin xyz="0 0 0" rpy="0 -0 0"/>
    <inertial>
      <origin xyz="0 0 0" rpy="0 0 0"/>
      <mass value="1e-9"/>
      <inertia ixx="0" ixy="0" ixz="0" iyy="0" iyz="0" izz="0"/>
    </inertial>
  </link>
  <joint name="left_front_foot_frame" type="fixed">
    <origin xyz="-0.048 6.93889e-18 -0.0165" rpy="3.14159 -1.14548e-30 -4.49613e-30"/>
    <parent link="bittle_x_shank_left"/>
    <child link="left_front_foot"/>
    <axis xyz="0 0 0"/>
  </joint>
  <!-- Joint from bittle_x_leg to bittle_x_shank_left -->
  <joint name="left_front_knee" type="revolute">
    <origin xyz="-0.046 3.68629e-13 -0.00215" rpy="-3.14159 2.77413e-16 1.5708"/>
    <parent link="bittle_x_leg"/>
    <child link="bittle_x_shank_left"/>
    <axis xyz="0 0 1"/>
    <limit effort="10" velocity="10" lower="-3.141592653589793" upper="3.141592653589793"/>
  </joint>
  <!-- Joint from chassis to bittle_x_leg -->
  <joint name="left_front" type="revolute">
    <origin xyz="0.0422033 -0.0501588 -0.000503935" rpy="1.08732e-17 -1.5708 0"/>
    <parent link="chassis"/>
    <child link="bittle_x_leg"/>
    <axis xyz="0 0 1"/>
    <limit effort="10" velocity="10" lower="-3.141592653589793" upper="3.141592653589793"/>
  </joint>
  <!-- Link bittle_x_leg_2 -->
  <link name="bittle_x_leg_2">
    <inertial>
      <origin xyz="-0.023 1.03756e-06 -0.00195" rpy="0 0 0"/>
      <mass value="0.00320032"/>
      <inertia ixx="6.4702e-08" ixy="-4.32909e-14" ixz="-4.44657e-08" iyy="1.08313e-06" iyz="-1.92002e-15" izz="1.11945e-06"/>
    </inertial>
    <!-- Part springs_v2_3 -->
    <visual>
      <origin xyz="-0.0100472 0.000102873 -0.000991506" rpy="-1.51844 4.99211e-05 -1.57175"/>
      <geometry>
        <mesh filename="package://assets/springs_v2.stl"/>
      </geometry>
      <material name="springs_v2_3_material">
        <color rgba="0.956863 0.898039 0.654902 1"/>
      </material>
    </visual>
    <!-- Part 809_25_v1_4 -->
    <visual>
      <origin xyz="-0.046 3.68677e-13 -0.00265" rpy="2.80217e-16 -1.58697e-31 3.14159"/>
      <geometry>
        <mesh filename="package://assets/809_25_v1.stl"/>
      </geometry>
      <material name="809_25_v1_4_material">
        <color rgba="0.752941 0.752941 0.752941 1"/>
      </material>
    </visual>
    <!-- Part 809_25_v1_5 -->
    <visual>
      <origin xyz="0 0 -0.0005" rpy="-1.33157e-33 3.85186e-33 8.00776e-29"/>
      <geometry>
        <mesh filename="package://assets/809_25_v1.stl"/>
      </geometry>
      <material name="809_25_v1_5_material">
        <color rgba="0.752941 0.752941 0.752941 1"/>
      </material>
    </visual>
    <!-- Part springs_v2_4 -->
    <visual>
      <origin xyz="-0.0429436 9.56526e-05 -0.00327486" rpy="-1.51844 -5.39851e-05 -1.56977"/>
      <geometry>
        <mesh filename="package://assets/springs_v2.stl"/>
      </geometry>
      <material name="springs_v2_4_material">
        <color rgba="0.956863 0.898039 0.654902 1"/>
      </material>
    </visual>
    <!-- Part thighsym_lower_2 -->
    <visual>
      <origin xyz="0.03 3.68296e-13 -0.002025" rpy="-1.5708 8.47409e-32 1.35446e-27"/>
      <geometry>
        <mesh filename="package://assets/thighsym_lower.stl"/>
      </geometry>
      <material name="thighsym_lower_2_material">
        <color rgba="0.356863 0.360784 0.368627 1"/>
      </material>
    </visual>
    <!-- Part thighsym_upper_2 -->
    <visual>
      <origin xyz="0.03 1.39472e-15 -0.00195" rpy="-1.5708 4.16001e-32 6.74788e-28"/>
      <geometry>
        <mesh filename="package://assets/thighsym_upper.stl"/>
      </geometry>
      <material name="thighsym_upper_2_material">
        <color rgba="0.980392 0.647059 0.239216 1"/>
      </material>
    </visual>
  </link>
  <!-- Frame right_front_knee (dummy link + fixed joint) -->
  <link name="right_front_knee">
    <origin xyz="0 0 0" rpy="0 -0 0"/>
    <inertial>
      <origin xyz="0 0 0" rpy="0 0 0"/>
      <mass value="1e-9"/>
      <inertia ixx="0" ixy="0" ixz="0" iyy="0" iyz="0" izz="0"/>
    </inertial>
  </link>
  <joint name="right_front_knee_frame" type="fixed">
    <origin xyz="-0.0554318 3.16934e-13 -0.0041" rpy="1.5708 -3.01693e-29 5.36902e-12"/>
    <parent link="bittle_x_leg_2"/>
    <child link="right_front_knee"/>
    <axis xyz="0 0 0"/>
  </joint>
  <!-- Link bittle_x_shank_right -->
  <link name="bittle_x_shank_right">
    <inertial>
      <origin xyz="-0.00799662 -0.00014001 -0.0160518" rpy="0 0 0"/>
      <mass value="0.0163164"/>
      <inertia ixx="7.33351e-07" ixy="-2.14772e-08" ixz="-1.54408e-07" iyy="2.51211e-06" iyz="-1.02466e-09" izz="2.23017e-06"/>
    </inertial>
    <!-- Part shank_2 -->
    <visual>
      <origin xyz="0.0061 0.0061 -0.0058" rpy="1.5708 1.5708 0"/>
      <geometry>
        <mesh filename="package://assets/shank.stl"/>
      </geometry>
      <material name="shank_2_material">
        <color rgba="0.286275 0.286275 0.27451 1"/>
      </material>
    </visual>
    <!-- Part kp_v5_shaft_6 -->
    <visual>
      <origin xyz="0.0061 -0.0061 -0.0272" rpy="-1.5708 -1.5708 0"/>
      <geometry>
        <mesh filename="package://assets/kp_v5_shaft.stl"/>
      </geometry>
      <material name="kp_v5_shaft_6_material">
        <color rgba="0.627451 0.627451 0.627451 1"/>
      </material>
    </visual>
    <!-- Part kp_v5_body_6 -->
    <visual>
      <origin xyz="0.0061 -0.0061 -0.0272" rpy="-1.5708 -1.5708 0"/>
      <geometry>
        <mesh filename="package://assets/kp_v5_body.stl"/>
      </geometry>
      <material name="kp_v5_body_6_material">
        <color rgba="0.152941 0.239216 0.2 1"/>
      </material>
    </visual>
  </link>
  <!-- Frame right_front_foot (dummy link + fixed joint) -->
  <link name="right_front_foot">
    <origin xyz="0 0 0" rpy="0 -0 0"/>
    <inertial>
      <origin xyz="0 0 0" rpy="0 0 0"/>
      <mass value="1e-9"/>
      <inertia ixx="0" ixy="0" ixz="0" iyy="0" iyz="0" izz="0"/>
    </inertial>
  </link>
  <joint name="right_front_foot_frame" type="fixed">
    <origin xyz="-0.048 6.93889e-18 -0.0165" rpy="7.70372e-33 2.77556e-16 -6.93889e-17"/>
    <parent link="bittle_x_shank_right"/>
    <child link="right_front_foot"/>
    <axis xyz="0 0 0"/>
  </joint>
  <!-- Joint from bittle_x_leg_2 to bittle_x_shank_right -->
  <joint name="right_front_knee" type="revolute">
    <origin xyz="-0.046 3.68677e-13 -0.00215" rpy="3.14159 -2.80217e-16 -1.5708"/>
    <parent link="bittle_x_leg_2"/>
    <child link="bittle_x_shank_right"/>
    <axis xyz="0 0 1"/>
    <limit effort="10" velocity="10" lower="-3.141592653589793" upper="3.141592653589793"/>
  </joint>
  <!-- Joint from chassis to bittle_x_leg_2 -->
  <joint name="right_front" type="revolute">
    <origin xyz="-0.0547292 -0.0501881 -0.000503935" rpy="-3.14159 -1.5708 0"/>
    <parent link="chassis"/>
    <child link="bittle_x_leg_2"/>
    <axis xyz="0 0 1"/>
    <limit effort="10" velocity="10" lower="-3.141592653589793" upper="3.141592653589793"/>
  </joint>
  <!-- Link bittle_x_leg_3 -->
  <link name="bittle_x_leg_3">
    <inertial>
      <origin xyz="-0.023 1.03756e-06 -0.00195" rpy="0 0 0"/>
      <mass value="0.00320032"/>
      <inertia ixx="6.4702e-08" ixy="-4.32909e-14" ixz="-4.44657e-08" iyy="1.08313e-06" iyz="-1.92002e-15" izz="1.11945e-06"/>
    </inertial>
    <!-- Part springs_v2_5 -->
    <visual>
      <origin xyz="-0.0100472 0.000102873 -0.000991506" rpy="-1.51844 4.99211e-05 -1.57175"/>
      <geometry>
        <mesh filename="package://assets/springs_v2.stl"/>
      </geometry>
      <material name="springs_v2_5_material">
        <color rgba="0.956863 0.898039 0.654902 1"/>
      </material>
    </visual>
    <!-- Part 809_25_v1_6 -->
    <visual>
      <origin xyz="-0.046 3.68656e-13 -0.00265" rpy="2.74609e-16 8.01187e-32 3.14159"/>
      <geometry>
        <mesh filename="package://assets/809_25_v1.stl"/>
      </geometry>
      <material name="809_25_v1_6_material">
        <color rgba="0.752941 0.752941 0.752941 1"/>
      </material>
    </visual>
    <!-- Part 809_25_v1_7 -->
    <visual>
      <origin xyz="-1.0842e-19 0 -0.0005" rpy="-6.24617e-33 -1.54074e-33 -4.07539e-29"/>
      <geometry>
        <mesh filename="package://assets/809_25_v1.stl"/>
      </geometry>
      <material name="809_25_v1_7_material">
        <color rgba="0.752941 0.752941 0.752941 1"/>
      </material>
    </visual>
    <!-- Part springs_v2_6 -->
    <visual>
      <origin xyz="-0.0429436 9.56526e-05 -0.00327486" rpy="-1.51844 -5.39851e-05 -1.56977"/>
      <geometry>
        <mesh filename="package://assets/springs_v2.stl"/>
      </geometry>
      <material name="springs_v2_6_material">
        <color rgba="0.956863 0.898039 0.654902 1"/>
      </material>
    </visual>
    <!-- Part thighsym_lower_3 -->
    <visual>
      <origin xyz="0.03 3.68282e-13 -0.002025" rpy="-1.5708 6.93889e-18 1.14721e-27"/>
      <geometry>
        <mesh filename="package://assets/thighsym_lower.stl"/>
      </geometry>
      <material name="thighsym_lower_3_material">
        <color rgba="0.356863 0.360784 0.368627 1"/>
      </material>
    </visual>
    <!-- Part thighsym_upper_3 -->
    <visual>
      <origin xyz="0.03 1.40166e-15 -0.00195" rpy="-1.5708 6.93889e-18 5.53229e-28"/>
      <geometry>
        <mesh filename="package://assets/thighsym_upper.stl"/>
      </geometry>
      <material name="thighsym_upper_3_material">
        <color rgba="0.980392 0.647059 0.239216 1"/>
      </material>
    </visual>
  </link>
  <!-- Frame right_back_knee (dummy link + fixed joint) -->
  <link name="right_back_knee">
    <origin xyz="0 0 0" rpy="0 -0 0"/>
    <inertial>
      <origin xyz="0 0 0" rpy="0 0 0"/>
      <mass value="1e-9"/>
      <inertia ixx="0" ixy="0" ixz="0" iyy="0" iyz="0" izz="0"/>
    </inertial>
  </link>
  <joint name="right_back_knee_frame" type="fixed">
    <origin xyz="-0.0554318 3.1692e-13 -0.0041" rpy="1.5708 6.93889e-18 5.36902e-12"/>
    <parent link="bittle_x_leg_3"/>
    <child link="right_back_knee"/>
    <axis xyz="0 0 0"/>
  </joint>
  <!-- Link bittle_x_shank_right_2 -->
  <link name="bittle_x_shank_right_2">
    <inertial>
      <origin xyz="-0.00799662 -0.00014001 -0.0160518" rpy="0 0 0"/>
      <mass value="0.0163164"/>
      <inertia ixx="7.33351e-07" ixy="-2.14772e-08" ixz="-1.54408e-07" iyy="2.51211e-06" iyz="-1.02466e-09" izz="2.23017e-06"/>
    </inertial>
    <!-- Part shank_3 -->
    <visual>
      <origin xyz="0.0061 0.0061 -0.0058" rpy="1.5708 1.5708 0"/>
      <geometry>
        <mesh filename="package://assets/shank.stl"/>
      </geometry>
      <material name="shank_3_material">
        <color rgba="0.286275 0.286275 0.27451 1"/>
      </material>
    </visual>
    <!-- Part kp_v5_shaft_7 -->
    <visual>
      <origin xyz="0.0061 -0.0061 -0.0272" rpy="-1.5708 -1.5708 0"/>
      <geometry>
        <mesh filename="package://assets/kp_v5_shaft.stl"/>
      </geometry>
      <material name="kp_v5_shaft_7_material">
        <color rgba="0.627451 0.627451 0.627451 1"/>
      </material>
    </visual>
    <!-- Part kp_v5_body_7 -->
    <visual>
      <origin xyz="0.0061 -0.0061 -0.0272" rpy="-1.5708 -1.5708 0"/>
      <geometry>
        <mesh filename="package://assets/kp_v5_body.stl"/>
      </geometry>
      <material name="kp_v5_body_7_material">
        <color rgba="0.152941 0.239216 0.2 1"/>
      </material>
    </visual>
  </link>
  <!-- Frame right_back_foot (dummy link + fixed joint) -->
  <link name="right_back_foot">
    <origin xyz="0 0 0" rpy="0 -0 0"/>
    <inertial>
      <origin xyz="0 0 0" rpy="0 0 0"/>
      <mass value="1e-9"/>
      <inertia ixx="0" ixy="0" ixz="0" iyy="0" iyz="0" izz="0"/>
    </inertial>
  </link>
  <joint name="right_back_foot_frame" type="fixed">
    <origin xyz="-0.048 6.93889e-18 -0.0165" rpy="9.24446e-33 2.77556e-16 -6.93889e-17"/>
    <parent link="bittle_x_shank_right_2"/>
    <child link="right_back_foot"/>
    <axis xyz="0 0 0"/>
  </joint>
  <!-- Joint from bittle_x_leg_3 to bittle_x_shank_right_2 -->
  <joint name="right_back_knee" type="revolute">
    <origin xyz="-0.046 3.6865e-13 -0.00215" rpy="-3.14159 -2.74609e-16 -1.5708"/>
    <parent link="bittle_x_leg_3"/>
    <child link="bittle_x_shank_right_2"/>
    <axis xyz="0 0 1"/>
    <limit effort="10" velocity="10" lower="-3.141592653589793" upper="3.141592653589793"/>
  </joint>
  <!-- Joint from chassis to bittle_x_leg_3 -->
  <joint name="right_back" type="revolute">
    <origin xyz="-0.0547292 0.0548119 -0.000503935" rpy="-3.14159 -1.5708 0"/>
    <parent link="chassis"/>
    <child link="bittle_x_leg_3"/>
    <axis xyz="0 0 1"/>
    <limit effort="10" velocity="10" lower="-3.141592653589793" upper="3.141592653589793"/>
  </joint>
  <!-- Link bittle_x_leg_4 -->
  <link name="bittle_x_leg_4">
    <inertial>
      <origin xyz="-0.023 1.03756e-06 -0.00195" rpy="0 0 0"/>
      <mass value="0.00320032"/>
      <inertia ixx="6.4702e-08" ixy="-4.32909e-14" ixz="-4.44657e-08" iyy="1.08313e-06" iyz="-1.92002e-15" izz="1.11945e-06"/>
    </inertial>
    <!-- Part springs_v2_7 -->
    <visual>
      <origin xyz="-0.0100472 0.000102873 -0.000991506" rpy="-1.51844 4.99211e-05 -1.57175"/>
      <geometry>
        <mesh filename="package://assets/springs_v2.stl"/>
      </geometry>
      <material name="springs_v2_7_material">
        <color rgba="0.956863 0.898039 0.654902 1"/>
      </material>
    </visual>
    <!-- Part 809_25_v1_8 -->
    <visual>
      <origin xyz="-0.046 3.68636e-13 -0.00265" rpy="2.24001e-16 -1.57156e-31 3.14159"/>
      <geometry>
        <mesh filename="package://assets/809_25_v1.stl"/>
      </geometry>
      <material name="809_25_v1_8_material">
        <color rgba="0.752941 0.752941 0.752941 1"/>
      </material>
    </visual>
    <!-- Part 809_25_v1_9 -->
    <visual>
      <origin xyz="0 -6.93889e-18 -0.0005" rpy="6.67781e-33 -9.24446e-33 4.54689e-30"/>
      <geometry>
        <mesh filename="package://assets/809_25_v1.stl"/>
      </geometry>
      <material name="809_25_v1_9_material">
        <color rgba="0.752941 0.752941 0.752941 1"/>
      </material>
    </visual>
    <!-- Part springs_v2_8 -->
    <visual>
      <origin xyz="-0.0429436 9.56526e-05 -0.00327486" rpy="-1.51844 -5.39851e-05 -1.56977"/>
      <geometry>
        <mesh filename="package://assets/springs_v2.stl"/>
      </geometry>
      <material name="springs_v2_8_material">
        <color rgba="0.956863 0.898039 0.654902 1"/>
      </material>
    </visual>
    <!-- Part thighsym_lower_4 -->
    <visual>
      <origin xyz="0.03 3.68289e-13 -0.002025" rpy="-1.5708 6.16298e-32 -5.55112e-17"/>
      <geometry>
        <mesh filename="package://assets/thighsym_lower.stl"/>
      </geometry>
      <material name="thighsym_lower_4_material">
        <color rgba="0.356863 0.360784 0.368627 1"/>
      </material>
    </visual>
    <!-- Part thighsym_upper_4 -->
    <visual>
      <origin xyz="0.03 1.39472e-15 -0.00195" rpy="-1.5708 1.84889e-32 -5.04871e-28"/>
      <geometry>
        <mesh filename="package://assets/thighsym_upper.stl"/>
      </geometry>
      <material name="thighsym_upper_4_material">
        <color rgba="0.980392 0.647059 0.239216 1"/>
      </material>
    </visual>
  </link>
  <!-- Frame left_back_knee (dummy link + fixed joint) -->
  <link name="left_back_knee">
    <origin xyz="0 0 0" rpy="0 -0 0"/>
    <inertial>
      <origin xyz="0 0 0" rpy="0 0 0"/>
      <mass value="1e-9"/>
      <inertia ixx="0" ixy="0" ixz="0" iyy="0" iyz="0" izz="0"/>
    </inertial>
  </link>
  <joint name="left_back_knee_frame" type="fixed">
    <origin xyz="-0.0554318 3.16934e-13 -0.0041" rpy="1.5708 -2.65902e-28 5.36897e-12"/>
    <parent link="bittle_x_leg_4"/>
    <child link="left_back_knee"/>
    <axis xyz="0 0 0"/>
  </joint>
  <!-- Link bittle_x_shank_left_2 -->
  <link name="bittle_x_shank_left_2">
    <inertial>
      <origin xyz="-0.00799662 0.00014001 -0.0160518" rpy="0 0 0"/>
      <mass value="0.0163164"/>
      <inertia ixx="7.33351e-07" ixy="2.14772e-08" ixz="-1.54392e-07" iyy="2.51211e-06" iyz="1.02325e-09" izz="2.23017e-06"/>
    </inertial>
    <!-- Part shank_4 -->
    <visual>
      <origin xyz="0.0061 -0.0061 -0.0272" rpy="-1.5708 -1.5708 0"/>
      <geometry>
        <mesh filename="package://assets/shank.stl"/>
      </geometry>
      <material name="shank_4_material">
        <color rgba="0.286275 0.286275 0.27451 1"/>
      </material>
    </visual>
    <!-- Part kp_v5_shaft_8 -->
    <visual>
      <origin xyz="0.0061 -0.0061 -0.0272" rpy="-1.5708 -1.5708 0"/>
      <geometry>
        <mesh filename="package://assets/kp_v5_shaft.stl"/>
      </geometry>
      <material name="kp_v5_shaft_8_material">
        <color rgba="0.627451 0.627451 0.627451 1"/>
      </material>
    </visual>
    <!-- Part kp_v5_body_8 -->
    <visual>
      <origin xyz="0.0061 -0.0061 -0.0272" rpy="-1.5708 -1.5708 0"/>
      <geometry>
        <mesh filename="package://assets/kp_v5_body.stl"/>
      </geometry>
      <material name="kp_v5_body_8_material">
        <color rgba="0.152941 0.239216 0.2 1"/>
      </material>
    </visual>
  </link>
  <!-- Frame left_back_foot (dummy link + fixed joint) -->
  <link name="left_back_foot">
    <origin xyz="0 0 0" rpy="0 -0 0"/>
    <inertial>
      <origin xyz="0 0 0" rpy="0 0 0"/>
      <mass value="1e-9"/>
      <inertia ixx="0" ixy="0" ixz="0" iyy="0" iyz="0" izz="0"/>
    </inertial>
  </link>
  <joint name="left_back_foot_frame" type="fixed">
    <origin xyz="-0.048 0 -0.0165" rpy="-3.14159 -1.56548e-30 -1.34966e-29"/>
    <parent link="bittle_x_shank_left_2"/>
    <child link="left_back_foot"/>
    <axis xyz="0 0 0"/>
  </joint>
  <!-- Joint from bittle_x_leg_4 to bittle_x_shank_left_2 -->
  <joint name="left_back_knee" type="revolute">
    <origin xyz="-0.046 3.68636e-13 -0.00215" rpy="-3.14159 2.24001e-16 1.5708"/>
    <parent link="bittle_x_leg_4"/>
    <child link="bittle_x_shank_left_2"/>
    <axis xyz="0 0 1"/>
    <limit effort="10" velocity="10" lower="-3.141592653589793" upper="3.141592653589793"/>
  </joint>
  <!-- Joint from chassis to bittle_x_leg_4 -->
  <joint name="left_back" type="revolute">
    <origin xyz="0.0422033 0.0548412 -0.000503935" rpy="1.68824e-17 -1.5708 0"/>
    <parent link="chassis"/>
    <child link="bittle_x_leg_4"/>
    <axis xyz="0 0 1"/>
    <limit effort="10" velocity="10" lower="-3.141592653589793" upper="3.141592653589793"/>
  </joint>
  <!-- Link bittle_x_head -->
  <link name="bittle_x_head">
    <inertial>
      <origin xyz="-0.00717805 -2.62479e-05 -0.0227251" rpy="0 0 0"/>
      <mass value="0.022581"/>
      <inertia ixx="4.39226e-06" ixy="-1.68238e-09" ixz="-6.5665e-07" iyy="5.55585e-06" iyz="-1.16009e-08" izz="3.3521e-06"/>
    </inertial>
    <!-- Part head_1 -->
    <visual>
      <origin xyz="0.0316003 -1.01481e-16 0.0262667" rpy="-2.61799 7.01721e-32 -1.5708"/>
      <geometry>
        <mesh filename="package://assets/head_1.stl"/>
      </geometry>
      <material name="head_1_material">
        <color rgba="0.356863 0.682353 0.933333 1"/>
      </material>
    </visual>
    <!-- Part head_3 -->
    <visual>
      <origin xyz="0.0316003 -0.000126582 0.0262667" rpy="-2.61799 -2.18301e-32 -1.5708"/>
      <geometry>
        <mesh filename="package://assets/head_3.stl"/>
      </geometry>
      <material name="head_3_material">
        <color rgba="1 0.670588 0.313725 1"/>
      </material>
    </visual>
    <!-- Part head_2 -->
    <visual>
      <origin xyz="0.0316003 -0.000126582 0.0262667" rpy="-2.61799 7.01721e-32 -1.5708"/>
      <geometry>
        <mesh filename="package://assets/head_2.stl"/>
      </geometry>
      <material name="head_2_material">
        <color rgba="1 0.670588 0.313725 1"/>
      </material>
    </visual>
    <!-- Part kp_v5_shaft_9 -->
    <visual>
      <origin xyz="0.0061 -0.0061 -0.0272" rpy="-1.5708 -1.5708 0"/>
      <geometry>
        <mesh filename="package://assets/kp_v5_shaft.stl"/>
      </geometry>
      <material name="kp_v5_shaft_9_material">
        <color rgba="0.627451 0.627451 0.627451 1"/>
      </material>
    </visual>
    <!-- Part kp_v5_body_9 -->
    <visual>
      <origin xyz="0.0061 -0.0061 -0.0272" rpy="-1.5708 -1.5708 0"/>
      <geometry>
        <mesh filename="package://assets/kp_v5_body.stl"/>
      </geometry>
      <material name="kp_v5_body_9_material">
        <color rgba="0.152941 0.239216 0.2 1"/>
      </material>
    </visual>
  </link>
  <!-- Frame head (dummy link + fixed joint) -->
  <link name="head">
    <origin xyz="0 0 0" rpy="0 -0 0"/>
    <inertial>
      <origin xyz="0 0 0" rpy="0 0 0"/>
      <mass value="1e-9"/>
      <inertia ixx="0" ixy="0" ixz="0" iyy="0" iyz="0" izz="0"/>
    </inertial>
  </link>
  <joint name="head_frame" type="fixed">
    <origin xyz="-0.00456954 -0.00012664 -0.0434696" rpy="-2.74378 7.34748e-32 -1.5708"/>
    <parent link="bittle_x_head"/>
    <child link="head"/>
    <axis xyz="0 0 0"/>
  </joint>
  <!-- Joint from chassis to bittle_x_head -->
  <joint name="head" type="revolute">
    <origin xyz="-0.00626294 -0.0435043 0.01074" rpy="3.14159 -0.523599 1.5708"/>
    <parent link="chassis"/>
    <child link="bittle_x_head"/>
    <axis xyz="0 0 1"/>
    <limit effort="10" velocity="10" lower="-3.141592653589793" upper="3.141592653589793"/>
  </joint>
</robot>
